Workbook

Sheet 00_README
A1: Master Research Dataset -- Perceived Usability vs Objective Task Performance
A3: Title | B3: Evaluating the Alignment Between Perceived Usability and Objective Task Performance in a GraphRAG-Based Campus Virtual Assistant
A4: Purpose of this dataset | B4: Master, reusable observation-level dataset joining the human ASQ usability study to objective production task-performance, latency, and citation-correctness records, for direct statistical analysis in Excel, Python, R, or SPSS.
A5: Dataset build date | B5: 2026-08-10
A6: Data sources | B6: Sole source: campus-va/evaluation/reports/2026-08-02/raw_joined_by_scenario.csv -- an already-anonymized (R01-R22, no PII), already-validated join of the 2026-07-16 human ASQ study (evaluation/reports/2026-07-16/sus_asq_final/) to production chat_evaluation_logs/citation_evaluation_logs via trace_id. See evaluation/reports/2026-08-02/README.md for the original build methodology and evaluation/scripts/build_asq_scenario_excel_2026-08-02.py for the reused statistical functions.
A7: Reconstruction method | B7: This workbook independently re-derives every statistic from the same source CSV using the same computational methods as the already-published 2026-08-02 report (functions ported verbatim, see build_research_dataset_excel_2026-08-10.py), then compares the recomputed values against that report and against the numbers explicitly reported in the paper (sheet 09_STATISTICAL_SUMMARY, reconciliation table). No respondent, score, or statistic in this workbook was invented, adjusted, or back-fit to match a target number.
A8: n participants | B8: 22
A9: n observations | B9: 43
A10: n scenarios | B10: 2 (S1 = normal campus/registration questions, S2 = difficult/ambiguous/manipulative questions)
A11: Why 43, not 44 (22x2) | B11: One participant (P016) has only an S1 observation -- no S2 row exists in the source data. This is a genuine gap in the original study, not an artifact of this reconstruction; see 10_DATA_QUALITY and 02_PARTICIPANTS.
A12: Meaning of NA | B12: NA denotes a field that is genuinely unavailable in the traceable source data (e.g. scrubbed for privacy, or never captured at this grain). Every NA has an accompanying missing_reason. No NA was estimated or imputed.
A13: SUS data (out of scope) | B13: A related instrument, the System Usability Scale (SUS, 21 respondents, mean 69.05/100), was also collected in this project but is out of scope for this ASQ-focused paper and is deliberately excluded from this workbook. See evaluation/reports/2026-07-16/sus_asq_final/ if needed later.
A14: Citation-correctness scope warning | B14: This dataset's citation-correctness figures (07_CITATION_EVALUATION, 08, 09) are per-observation values tied to the 22 real participants. A separate, unrelated 41-question automated gold-QA benchmark also reports a citation-correct rate (39.0%) -- that is a DIFFERENT instrument, not tied to these participants, and is not merged into this dataset's figures anywhere.
... A18: Data integrity statement | B18: Dataset ini disusun dari data eksperimen, log sistem, dan hasil evaluasi yang tersedia. Missing values tidak diimputasi kecuali dinyatakan secara eksplisit. No respondent, score, or statistic was fabricated to match a reported paper value; see the reconciliation table in 09_STATISTICAL_SUMMARY and dataset_reconstruction_report.md for an explicit comparison.

Sheet 01_CODEBOOK
A1: variable_name | B1: sheet | C1: data_type | D1: description | E1: unit | F1: allowed_value | G1: missing_rule | H1: analysis_role | I1: source | J1: is_formula
A2: participant_id | B2: 02_PARTICIPANTS | C2: string | D2: Anonymous participant identifier | F2: P001-P022 | H2: primary key | I2: derived: R0x (2026-08-02 linkage) -> P0xx by numeric suffix | J2: N
A3: participant_code | B3: 02_PARTICIPANTS | C3: string | D3: Alias of participant_id; no separate real code retained | H3: identifier | I3: formula: same as participant_id | J3: Y
A4: participant_group | B4: 02_PARTICIPANTS | C4: string | D4: Participant category (student/prospective student/staff) | F4: NA | G4: not recorded anywhere in the source data | H4: grouping (unavailable) | I4: NA | J4: N
A5: completed_s1 | B5: 02_PARTICIPANTS | C5: boolean | D5: Whether this participant has an S1 observation | I5: COUNTIFS over 03_OBSERVATIONS | J5: Y
A6: completed_s2 | B6: 02_PARTICIPANTS | C6: boolean | D6: Whether this participant has an S2 observation | I6: COUNTIFS over 03_OBSERVATIONS | J6: Y
A7: total_observations | B7: 02_PARTICIPANTS | C7: integer | D7: Count of observation rows for this participant | I7: COUNTIF over 03_OBSERVATIONS | J7: Y
A8: notes | B8: 02_PARTICIPANTS | C8: string | D8: Free-text note (e.g. missing scenario) | I8: derived | J8: N
A9: observation_id | B9: 03_OBSERVATIONS | C9: string | D9: Unique observation identifier | F9: OBS001-OBS043 | H9: primary key | I9: derived: sequential, sorted by participant_id then scenario_id | J9: N
A10: participant_id | B10: 03_OBSERVATIONS | C10: string | D10: Participant this observation belongs to | H10: foreign key -> 02_PARTICIPANTS | I10: from raw_joined_by_scenario.csv (r0x) | J10: N
A11: scenario_id | B11: 03_OBSERVATIONS | C11: category | D11: Scenario | F11: S1/S2 | I11: raw_joined_by_scenario.csv:scenario | J11: N
A12: scenario_order | B12: 03_OBSERVATIONS | C12: integer | D12: 1=S1, 2=S2 | I12: formula: IF(scenario_id="S1",1,2) | J12: Y
A13: session_id | B13: 03_OBSERVATIONS | C13: string | D13: Production session identifier | F13: NA | G13: scrubbed from the safe/anonymized export for participant privacy | I13: NA | J13: N
A14: timestamp_start | B14: 03_OBSERVATIONS | C14: datetime | D14: Scenario start timestamp | F14: NA | G14: not present in the safe per-observation export | I14: NA | J14: N
A15: timestamp_end | B15: 03_OBSERVATIONS | C15: datetime | D15: Scenario end timestamp | F15: NA | G15: not present in the safe per-observation export | I15: NA | J15: N
A16: query_text | B16: 03_OBSERVATIONS | C16: string | D16: User question text | F16: NA | G16: not present in the safe per-observation export | I16: NA | J16: N
A17: response_id | B17: 03_OBSERVATIONS | C17: string | D17: System response identifier | F17: NA | G17: not present in the safe per-observation export | I17: NA | J17: N
A18: task_status | B18: 03_OBSERVATIONS | C18: category | D18: Production answer_status for this turn | F18: verified/out_of_domain/insufficient_context/fallback_enforced/needs_clarification/blank | G18: blank when no trace_id was linked (1 row: participant with no matched production turn) | I18: raw_joined_by_scenario.csv:answer_status | J18: N
A19: data_source | B19: 03_OBSERVATIONS | C19: string | D19: Provenance of this row | I19: derived: source file + row | J19: N
A20: missing_flag | B20: 03_OBSERVATIONS | C20: boolean | D20: TRUE if task_status is blank | I20: formula: IF(task_status="",TRUE,FALSE) | J20: Y
A21: missing_reason | B21: 03_OBSERVATIONS | C21: string | D21: Why task_status is blank, if applicable | I21: derived | J21: N
A22: observation_id | B22: 04_ASQ_RESPONSES | C22: string | D22: FK to 03_OBSERVATIONS | H22: foreign key | I22: formula: ='03_OBSERVATIONS' same row | J22: Y
A23: participant_id | B23: 04_ASQ_RESPONSES | C23: string | D23: FK to 02_PARTICIPANTS | I23: formula: ='03_OBSERVATIONS' same row | J23: Y
A24: scenario_id | B24: 04_ASQ_RESPONSES | C24: category | D24: S1/S2 | I24: formula: ='03_OBSERVATIONS' same row | J24: Y
A25: asq_q1_ease | B25: 04_ASQ_RESPONSES | C25: integer | D25: ASQ item 1: ease of completing the task | E25: 1-7 Likert | F25: 1-7 | I25: raw_joined_by_scenario.csv:asq_1 | J25: N
A26: asq_q2_time | B26: 04_ASQ_RESPONSES | C26: integer | D26: ASQ item 2: satisfaction with time taken | E26: 1-7 Likert | F26: 1-7 | I26: raw_joined_by_scenario.csv:asq_2 | J26: N
A27: asq_q3_information_support | B27: 04_ASQ_RESPONSES | C27: integer | D27: ASQ item 3: satisfaction with information/citations/messages | E27: 1-7 Likert | F27: 1-7 | I27: raw_joined_by_scenario.csv:asq_3 | J27: N
A28: asq_mean | B28: 04_ASQ_RESPONSES | C28: decimal | D28: Mean of the 3 ASQ items | E28: 1-7 | H28: primary DV (perceived usability) | I28: formula: AVERAGE(q1,q2,q3) | J28: Y
A29: asq_complete | B29: 04_ASQ_RESPONSES | C29: boolean | D29: TRUE iff all 3 items present | I29: formula: IF(COUNT(q1:q3)=3,TRUE,FALSE) | J29: Y
A30: asq_notes | B30: 04_ASQ_RESPONSES | C30: string | D30: Free-text note | I30: derived (source notes column empty) | J30: N
A31: observation_id | B31: 05_TASK_PERFORMANCE | C31: string | D31: FK | I31: same row as 03 | J31: Y
A32: participant_id | B32: 05_TASK_PERFORMANCE | C32: string | D32: FK | I32: same row as 03 | J32: Y
A33: scenario_id | B33: 05_TASK_PERFORMANCE | C33: category | D33: S1/S2 | I33: same row as 03 | J33: Y
A34: task_success | B34: 05_TASK_PERFORMANCE | C34: binary | D34: 1=success, 0=not success, blank=no linked turn | F34: 0/1/blank | H34: primary objective-performance DV | I34: raw_joined_by_scenario.csv:task_success (rule: answer_status in {answered, verified}) | J34: N
A35: task_status | B35: 05_TASK_PERFORMANCE | C35: category | D35: same as 03_OBSERVATIONS.task_status | I35: formula: ='03_OBSERVATIONS' same row | J35: Y
A36: completion_time_sec | B36: 05_TASK_PERFORMANCE | C36: numeric | D36: Completion time proxy | E36: seconds | I36: raw_joined_by_scenario.csv:completion_time_s | J36: N
A37: completion_time_source | B37: 05_TASK_PERFORMANCE | C37: string | D37: Constant: this is a proxy (ASQ-submission timestamp delta), not a stopwatch measurement | I37: constant | J37: N
A38: success_evidence | B38: 05_TASK_PERFORMANCE | C38: string | D38: Evidence text derived from task_status | I38: derived | J38: N
A39: evaluator_notes | B39: 05_TASK_PERFORMANCE | C39: string | D39: Flags negative/outlier completion-time rows per source's own validity flags | I39: derived | J39: N
A40: observation_id | B40: 06_SYSTEM_METRICS | C40: string | D40: FK | I40: same row as 03 | J40: Y
...

Sheet 02_PARTICIPANTS
A1: participant_id | B1: participant_code | C1: participant_group | D1: completed_s1 | E1: completed_s2 | F1: total_observations | G1: notes
A2: P001 | B2: =A2 | C2: NA | D2: =COUNTIFS('03_OBSERVATIONS'!$B:$B,A2,'03_OBSERVATIONS'!$C:$C,"S1")>0 | E2: =COUNTIFS('03_OBSERVATIONS'!$B:$B,A2,'03_OBSERVATIONS'!$C:$C,"S2")>0 | F2: =COUNTIF('03_OBSERVATIONS'!$B:$B,A2)
A3: P002 | B3: =A3 | C3: NA | D3: =COUNTIFS('03_OBSERVATIONS'!$B:$B,A3,'03_OBSERVATIONS'!$C:$C,"S1")>0 | E3: =COUNTIFS('03_OBSERVATIONS'!$B:$B,A3,'03_OBSERVATIONS'!$C:$C,"S2")>0 | F3: =COUNTIF('03_OBSERVATIONS'!$B:$B,A3)
A4: P003 | B4: =A4 | C4: NA | D4: =COUNTIFS('03_OBSERVATIONS'!$B:$B,A4,'03_OBSERVATIONS'!$C:$C,"S1")>0 | E4: =COUNTIFS('03_OBSERVATIONS'!$B:$B,A4,'03_OBSERVATIONS'!$C:$C,"S2")>0 | F4: =COUNTIF('03_OBSERVATIONS'!$B:$B,A4)
A5: P004 | B5: =A5 | C5: NA | D5: =COUNTIFS('03_OBSERVATIONS'!$B:$B,A5,'03_OBSERVATIONS'!$C:$C,"S1")>0 | E5: =COUNTIFS('03_OBSERVATIONS'!$B:$B,A5,'03_OBSERVATIONS'!$C:$C,"S2")>0 | F5: =COUNTIF('03_OBSERVATIONS'!$B:$B,A5)
A6: P005 | B6: =A6 | C6: NA | D6: =COUNTIFS('03_OBSERVATIONS'!$B:$B,A6,'03_OBSERVATIONS'!$C:$C,"S1")>0 | E6: =COUNTIFS('03_OBSERVATIONS'!$B:$B,A6,'03_OBSERVATIONS'!$C:$C,"S2")>0 | F6: =COUNTIF('03_OBSERVATIONS'!$B:$B,A6)
A7: P006 | B7: =A7 | C7: NA | D7: =COUNTIFS('03_OBSERVATIONS'!$B:$B,A7,'03_OBSERVATIONS'!$C:$C,"S1")>0 | E7: =COUNTIFS('03_OBSERVATIONS'!$B:$B,A7,'03_OBSERVATIONS'!$C:$C,"S2")>0 | F7: =COUNTIF('03_OBSERVATIONS'!$B:$B,A7)
A8: P007 | B8: =A8 | C8: NA | D8: =COUNTIFS('03_OBSERVATIONS'!$B:$B,A8,'03_OBSERVATIONS'!$C:$C,"S1")>0 | E8: =COUNTIFS('03_OBSERVATIONS'!$B:$B,A8,'03_OBSERVATIONS'!$C:$C,"S2")>0 | F8: =COUNTIF('03_OBSERVATIONS'!$B:$B,A8)
A9: P008 | B9: =A9 | C9: NA | D9: =COUNTIFS('03_OBSERVATIONS'!$B:$B,A9,'03_OBSERVATIONS'!$C:$C,"S1")>0 | E9: =COUNTIFS('03_OBSERVATIONS'!$B:$B,A9,'03_OBSERVATIONS'!$C:$C,"S2")>0 | F9: =COUNTIF('03_OBSERVATIONS'!$B:$B,A9)
A10: P009 | B10: =A10 | C10: NA | D10: =COUNTIFS('03_OBSERVATIONS'!$B:$B,A10,'03_OBSERVATIONS'!$C:$C,"S1")>0 | E10: =COUNTIFS('03_OBSERVATIONS'!$B:$B,A10,'03_OBSERVATIONS'!$C:$C,"S2")>0 | F10: =COUNTIF('03_OBSERVATIONS'!$B:$B,A10)
A11: P010 | B11: =A11 | C11: NA | D11: =COUNTIFS('03_OBSERVATIONS'!$B:$B,A11,'03_OBSERVATIONS'!$C:$C,"S1")>0 | E11: =COUNTIFS('03_OBSERVATIONS'!$B:$B,A11,'03_OBSERVATIONS'!$C:$C,"S2")>0 | F11: =COUNTIF('03_OBSERVATIONS'!$B:$B,A11)
A12: P011 | B12: =A12 | C12: NA | D12: =COUNTIFS('03_OBSERVATIONS'!$B:$B,A12,'03_OBSERVATIONS'!$C:$C,"S1")>0 | E12: =COUNTIFS('03_OBSERVATIONS'!$B:$B,A12,'03_OBSERVATIONS'!$C:$C,"S2")>0 | F12: =COUNTIF('03_OBSERVATIONS'!$B:$B,A12)
A13: P012 | B13: =A13 | C13: NA | D13: =COUNTIFS('03_OBSERVATIONS'!$B:$B,A13,'03_OBSERVATIONS'!$C:$C,"S1")>0 | E13: =COUNTIFS('03_OBSERVATIONS'!$B:$B,A13,'03_OBSERVATIONS'!$C:$C,"S2")>0 | F13: =COUNTIF('03_OBSERVATIONS'!$B:$B,A13)
... A16: P015 | B16: =A16 | C16: NA | D16: =COUNTIFS('03_OBSERVATIONS'!$B:$B,A16,'03_OBSERVATIONS'!$C:$C,"S1")>0 | E16: =COUNTIFS('03_OBSERVATIONS'!$B:$B,A16,'03_OBSERVATIONS'!$C:$C,"S2")>0 | F16: =COUNTIF('03_OBSERVATIONS'!$B:$B,A16)
A17: P016 | B17: =A17 | C17: NA | D17: =COUNTIFS('03_OBSERVATIONS'!$B:$B,A17,'03_OBSERVATIONS'!$C:$C,"S1")>0 | E17: =COUNTIFS('03_OBSERVATIONS'!$B:$B,A17,'03_OBSERVATIONS'!$C:$C,"S2")>0 | F17: =COUNTIF('03_OBSERVATIONS'!$B:$B,A17) | G17: No S2 observation on record (see 10_DATA_QUALITY)
A18: P017 | B18: =A18 | C18: NA | D18: =COUNTIFS('03_OBSERVATIONS'!$B:$B,A18,'03_OBSERVATIONS'!$C:$C,"S1")>0 | E18: =COUNTIFS('03_OBSERVATIONS'!$B:$B,A18,'03_OBSERVATIONS'!$C:$C,"S2")>0 | F18: =COUNTIF('03_OBSERVATIONS'!$B:$B,A18)
A19: P018 | B19: =A19 | C19: NA | D19: =COUNTIFS('03_OBSERVATIONS'!$B:$B,A19,'03_OBSERVATIONS'!$C:$C,"S1")>0 | E19: =COUNTIFS('03_OBSERVATIONS'!$B:$B,A19,'03_OBSERVATIONS'!$C:$C,"S2")>0 | F19: =COUNTIF('03_OBSERVATIONS'!$B:$B,A19)
A20: P019 | B20: =A20 | C20: NA | D20: =COUNTIFS('03_OBSERVATIONS'!$B:$B,A20,'03_OBSERVATIONS'!$C:$C,"S1")>0 | E20: =COUNTIFS('03_OBSERVATIONS'!$B:$B,A20,'03_OBSERVATIONS'!$C:$C,"S2")>0 | F20: =COUNTIF('03_OBSERVATIONS'!$B:$B,A20)
A21: P020 | B21: =A21 | C21: NA | D21: =COUNTIFS('03_OBSERVATIONS'!$B:$B,A21,'03_OBSERVATIONS'!$C:$C,"S1")>0 | E21: =COUNTIFS('03_OBSERVATIONS'!$B:$B,A21,'03_OBSERVATIONS'!$C:$C,"S2")>0 | F21: =COUNTIF('03_OBSERVATIONS'!$B:$B,A21)
A22: P021 | B22: =A22 | C22: NA | D22: =COUNTIFS('03_OBSERVATIONS'!$B:$B,A22,'03_OBSERVATIONS'!$C:$C,"S1")>0 | E22: =COUNTIFS('03_OBSERVATIONS'!$B:$B,A22,'03_OBSERVATIONS'!$C:$C,"S2")>0 | F22: =COUNTIF('03_OBSERVATIONS'!$B:$B,A22)
A23: P022 | B23: =A23 | C23: NA | D23: =COUNTIFS('03_OBSERVATIONS'!$B:$B,A23,'03_OBSERVATIONS'!$C:$C,"S1")>0 | E23: =COUNTIFS('03_OBSERVATIONS'!$B:$B,A23,'03_OBSERVATIONS'!$C:$C,"S2")>0 | F23: =COUNTIF('03_OBSERVATIONS'!$B:$B,A23)

Sheet 03_OBSERVATIONS
A1: observation_id | B1: participant_id | C1: scenario_id | D1: scenario_order | E1: session_id | F1: timestamp_start | G1: timestamp_end | H1: query_text | I1: response_id | J1: task_status | K1: data_source | L1: missing_flag | M1: missing_reason
A2: OBS001 | B2: P001 | C2: S1 | D2: =IF(C2="S1",1,2) | E2: NA | F2: NA | G2: NA | H2: NA | I2: NA | J2: verified | K2: raw_joined_by_scenario.csv row 1 (r0x=R01) | L2: =IF(J2="",TRUE,FALSE)
A3: OBS002 | B3: P001 | C3: S2 | D3: =IF(C3="S1",1,2) | E3: NA | F3: NA | G3: NA | H3: NA | I3: NA | J3: verified | K3: raw_joined_by_scenario.csv row 2 (r0x=R01) | L3: =IF(J3="",TRUE,FALSE)
A4: OBS003 | B4: P002 | C4: S1 | D4: =IF(C4="S1",1,2) | E4: NA | F4: NA | G4: NA | H4: NA | I4: NA | J4: verified | K4: raw_joined_by_scenario.csv row 3 (r0x=R02) | L4: =IF(J4="",TRUE,FALSE)
A5: OBS004 | B5: P002 | C5: S2 | D5: =IF(C5="S1",1,2) | E5: NA | F5: NA | G5: NA | H5: NA | I5: NA | J5: verified | K5: raw_joined_by_scenario.csv row 4 (r0x=R02) | L5: =IF(J5="",TRUE,FALSE)
A6: OBS005 | B6: P003 | C6: S1 | D6: =IF(C6="S1",1,2) | E6: NA | F6: NA | G6: NA | H6: NA | I6: NA | J6: verified | K6: raw_joined_by_scenario.csv row 5 (r0x=R03) | L6: =IF(J6="",TRUE,FALSE)
A7: OBS006 | B7: P003 | C7: S2 | D7: =IF(C7="S1",1,2) | E7: NA | F7: NA | G7: NA | H7: NA | I7: NA | J7: verified | K7: raw_joined_by_scenario.csv row 6 (r0x=R03) | L7: =IF(J7="",TRUE,FALSE)
A8: OBS007 | B8: P004 | C8: S1 | D8: =IF(C8="S1",1,2) | E8: NA | F8: NA | G8: NA | H8: NA | I8: NA | J8: out_of_domain | K8: raw_joined_by_scenario.csv row 7 (r0x=R04) | L8: =IF(J8="",TRUE,FALSE)
A9: OBS008 | B9: P004 | C9: S2 | D9: =IF(C9="S1",1,2) | E9: NA | F9: NA | G9: NA | H9: NA | I9: NA | J9: out_of_domain | K9: raw_joined_by_scenario.csv row 8 (r0x=R04) | L9: =IF(J9="",TRUE,FALSE)
A10: OBS009 | B10: P005 | C10: S1 | D10: =IF(C10="S1",1,2) | E10: NA | F10: NA | G10: NA | H10: NA | I10: NA | J10: fallback_enforced | K10: raw_joined_by_scenario.csv row 9 (r0x=R05) | L10: =IF(J10="",TRUE,FALSE)
A11: OBS010 | B11: P005 | C11: S2 | D11: =IF(C11="S1",1,2) | E11: NA | F11: NA | G11: NA | H11: NA | I11: NA | J11: out_of_domain | K11: raw_joined_by_scenario.csv row 10 (r0x=R05) | L11: =IF(J11="",TRUE,FALSE)
A12: OBS011 | B12: P006 | C12: S1 | D12: =IF(C12="S1",1,2) | E12: NA | F12: NA | G12: NA | H12: NA | I12: NA | K12: raw_joined_by_scenario.csv row 11 (r0x=R06) | L12: =IF(J12="",TRUE,FALSE) | M12: no linked trace_id for this turn in the production source
A13: OBS012 | B13: P006 | C13: S2 | D13: =IF(C13="S1",1,2) | E13: NA | F13: NA | G13: NA | H13: NA | I13: NA | J13: out_of_domain | K13: raw_joined_by_scenario.csv row 12 (r0x=R06) | L13: =IF(J13="",TRUE,FALSE)
A14: OBS013 | B14: P007 | C14: S1 | D14: =IF(C14="S1",1,2) | E14: NA | F14: NA | G14: NA | H14: NA | I14: NA | J14: insufficient_context | K14: raw_joined_by_scenario.csv row 13 (r0x=R07) | L14: =IF(J14="",TRUE,FALSE)
A15: OBS014 | B15: P007 | C15: S2 | D15: =IF(C15="S1",1,2) | E15: NA | F15: NA | G15: NA | H15: NA | I15: NA | J15: verified | K15: raw_joined_by_scenario.csv row 14 (r0x=R07) | L15: =IF(J15="",TRUE,FALSE)
A16: OBS015 | B16: P008 | C16: S1 | D16: =IF(C16="S1",1,2) | E16: NA | F16: NA | G16: NA | H16: NA | I16: NA | J16: out_of_domain | K16: raw_joined_by_scenario.csv row 15 (r0x=R08) | L16: =IF(J16="",TRUE,FALSE)
A17: OBS016 | B17: P008 | C17: S2 | D17: =IF(C17="S1",1,2) | E17: NA | F17: NA | G17: NA | H17: NA | I17: NA | J17: verified | K17: raw_joined_by_scenario.csv row 16 (r0x=R08) | L17: =IF(J17="",TRUE,FALSE)
A18: OBS017 | B18: P009 | C18: S1 | D18: =IF(C18="S1",1,2) | E18: NA | F18: NA | G18: NA | H18: NA | I18: NA | J18: out_of_domain | K18: raw_joined_by_scenario.csv row 17 (r0x=R09) | L18: =IF(J18="",TRUE,FALSE)
A19: OBS018 | B19: P009 | C19: S2 | D19: =IF(C19="S1",1,2) | E19: NA | F19: NA | G19: NA | H19: NA | I19: NA | J19: out_of_domain | K19: raw_joined_by_scenario.csv row 18 (r0x=R09) | L19: =IF(J19="",TRUE,FALSE)
A20: OBS019 | B20: P010 | C20: S1 | D20: =IF(C20="S1",1,2) | E20: NA | F20: NA | G20: NA | H20: NA | I20: NA | J20: insufficient_context | K20: raw_joined_by_scenario.csv row 19 (r0x=R10) | L20: =IF(J20="",TRUE,FALSE)
A21: OBS020 | B21: P010 | C21: S2 | D21: =IF(C21="S1",1,2) | E21: NA | F21: NA | G21: NA | H21: NA | I21: NA | J21: insufficient_context | K21: raw_joined_by_scenario.csv row 20 (r0x=R10) | L21: =IF(J21="",TRUE,FALSE)
A22: OBS021 | B22: P011 | C22: S1 | D22: =IF(C22="S1",1,2) | E22: NA | F22: NA | G22: NA | H22: NA | I22: NA | J22: insufficient_context | K22: raw_joined_by_scenario.csv row 21 (r0x=R11) | L22: =IF(J22="",TRUE,FALSE)
A23: OBS022 | B23: P011 | C23: S2 | D23: =IF(C23="S1",1,2) | E23: NA | F23: NA | G23: NA | H23: NA | I23: NA | J23: insufficient_context | K23: raw_joined_by_scenario.csv row 22 (r0x=R11) | L23: =IF(J23="",TRUE,FALSE)
A24: OBS023 | B24: P012 | C24: S1 | D24: =IF(C24="S1",1,2) | E24: NA | F24: NA | G24: NA | H24: NA | I24: NA | J24: needs_clarification | K24: raw_joined_by_scenario.csv row 23 (r0x=R12) | L24: =IF(J24="",TRUE,FALSE)
... A44: OBS043 | B44: P022 | C44: S2 | D44: =IF(C44="S1",1,2) | E44: NA | F44: NA | G44: NA | H44: NA | I44: NA | J44: verified | K44: raw_joined_by_scenario.csv row 43 (r0x=R22) | L44: =IF(J44="",TRUE,FALSE)

Sheet 04_ASQ_RESPONSES
A1: observation_id | B1: participant_id | C1: scenario_id | D1: asq_q1_ease | E1: asq_q2_time | F1: asq_q3_information_support | G1: asq_mean | H1: asq_complete | I1: asq_notes
A2: ='03_OBSERVATIONS'!A2 | B2: ='03_OBSERVATIONS'!B2 | C2: ='03_OBSERVATIONS'!C2 | D2: 7 | E2: 7 | F2: 7 | G2: =AVERAGE(D2:F2) | H2: =IF(COUNT(D2:F2)=3,TRUE,FALSE)
A3: ='03_OBSERVATIONS'!A3 | B3: ='03_OBSERVATIONS'!B3 | C3: ='03_OBSERVATIONS'!C3 | D3: 7 | E3: 7 | F3: 7 | G3: =AVERAGE(D3:F3) | H3: =IF(COUNT(D3:F3)=3,TRUE,FALSE)
A4: ='03_OBSERVATIONS'!A4 | B4: ='03_OBSERVATIONS'!B4 | C4: ='03_OBSERVATIONS'!C4 | D4: 5 | E4: 5 | F4: 6 | G4: =AVERAGE(D4:F4) | H4: =IF(COUNT(D4:F4)=3,TRUE,FALSE)
A5: ='03_OBSERVATIONS'!A5 | B5: ='03_OBSERVATIONS'!B5 | C5: ='03_OBSERVATIONS'!C5 | D5: 5 | E5: 5 | F5: 6 | G5: =AVERAGE(D5:F5) | H5: =IF(COUNT(D5:F5)=3,TRUE,FALSE)
A6: ='03_OBSERVATIONS'!A6 | B6: ='03_OBSERVATIONS'!B6 | C6: ='03_OBSERVATIONS'!C6 | D6: 7 | E6: 7 | F6: 7 | G6: =AVERAGE(D6:F6) | H6: =IF(COUNT(D6:F6)=3,TRUE,FALSE)
A7: ='03_OBSERVATIONS'!A7 | B7: ='03_OBSERVATIONS'!B7 | C7: ='03_OBSERVATIONS'!C7 | D7: 5 | E7: 5 | F7: 5 | G7: =AVERAGE(D7:F7) | H7: =IF(COUNT(D7:F7)=3,TRUE,FALSE)
A8: ='03_OBSERVATIONS'!A8 | B8: ='03_OBSERVATIONS'!B8 | C8: ='03_OBSERVATIONS'!C8 | D8: 4 | E8: 4 | F8: 4 | G8: =AVERAGE(D8:F8) | H8: =IF(COUNT(D8:F8)=3,TRUE,FALSE)
A9: ='03_OBSERVATIONS'!A9 | B9: ='03_OBSERVATIONS'!B9 | C9: ='03_OBSERVATIONS'!C9 | D9: 4 | E9: 4 | F9: 4 | G9: =AVERAGE(D9:F9) | H9: =IF(COUNT(D9:F9)=3,TRUE,FALSE)
A10: ='03_OBSERVATIONS'!A10 | B10: ='03_OBSERVATIONS'!B10 | C10: ='03_OBSERVATIONS'!C10 | D10: 7 | E10: 7 | F10: 5 | G10: =AVERAGE(D10:F10) | H10: =IF(COUNT(D10:F10)=3,TRUE,FALSE)
A11: ='03_OBSERVATIONS'!A11 | B11: ='03_OBSERVATIONS'!B11 | C11: ='03_OBSERVATIONS'!C11 | D11: 7 | E11: 7 | F11: 7 | G11: =AVERAGE(D11:F11) | H11: =IF(COUNT(D11:F11)=3,TRUE,FALSE)
A12: ='03_OBSERVATIONS'!A12 | B12: ='03_OBSERVATIONS'!B12 | C12: ='03_OBSERVATIONS'!C12 | D12: 7 | E12: 7 | F12: 7 | G12: =AVERAGE(D12:F12) | H12: =IF(COUNT(D12:F12)=3,TRUE,FALSE)
A13: ='03_OBSERVATIONS'!A13 | B13: ='03_OBSERVATIONS'!B13 | C13: ='03_OBSERVATIONS'!C13 | D13: 7 | E13: 7 | F13: 7 | G13: =AVERAGE(D13:F13) | H13: =IF(COUNT(D13:F13)=3,TRUE,FALSE)
... A44: ='03_OBSERVATIONS'!A44 | B44: ='03_OBSERVATIONS'!B44 | C44: ='03_OBSERVATIONS'!C44 | D44: 7 | E44: 7 | F44: 7 | G44: =AVERAGE(D44:F44) | H44: =IF(COUNT(D44:F44)=3,TRUE,FALSE)

Sheet 05_TASK_PERFORMANCE
A1: observation_id | B1: participant_id | C1: scenario_id | D1: task_success | E1: task_status | F1: completion_time_sec | G1: completion_time_source | H1: success_evidence | I1: evaluator_notes
A2: ='03_OBSERVATIONS'!A2 | B2: ='03_OBSERVATIONS'!B2 | C2: ='03_OBSERVATIONS'!C2 | D2: 1 | E2: ='03_OBSERVATIONS'!J2 | F2: 8.799037 | G2: proxy: ASQ-submission timestamp delta, not stopwatch | H2: answer_status=verified
A3: ='03_OBSERVATIONS'!A3 | B3: ='03_OBSERVATIONS'!B3 | C3: ='03_OBSERVATIONS'!C3 | D3: 1 | E3: ='03_OBSERVATIONS'!J3 | F3: 54.778502 | G3: proxy: ASQ-submission timestamp delta, not stopwatch | H3: answer_status=verified
A4: ='03_OBSERVATIONS'!A4 | B4: ='03_OBSERVATIONS'!B4 | C4: ='03_OBSERVATIONS'!C4 | D4: 1 | E4: ='03_OBSERVATIONS'!J4 | F4: 65.620526 | G4: proxy: ASQ-submission timestamp delta, not stopwatch | H4: answer_status=verified
A5: ='03_OBSERVATIONS'!A5 | B5: ='03_OBSERVATIONS'!B5 | C5: ='03_OBSERVATIONS'!C5 | D5: 1 | E5: ='03_OBSERVATIONS'!J5 | F5: 239.23709 | G5: proxy: ASQ-submission timestamp delta, not stopwatch | H5: answer_status=verified
A6: ='03_OBSERVATIONS'!A6 | B6: ='03_OBSERVATIONS'!B6 | C6: ='03_OBSERVATIONS'!C6 | D6: 1 | E6: ='03_OBSERVATIONS'!J6 | F6: 302.65578 | G6: proxy: ASQ-submission timestamp delta, not stopwatch | H6: answer_status=verified
A7: ='03_OBSERVATIONS'!A7 | B7: ='03_OBSERVATIONS'!B7 | C7: ='03_OBSERVATIONS'!C7 | D7: 1 | E7: ='03_OBSERVATIONS'!J7 | F7: 393.31036 | G7: proxy: ASQ-submission timestamp delta, not stopwatch | H7: answer_status=verified
A8: ='03_OBSERVATIONS'!A8 | B8: ='03_OBSERVATIONS'!B8 | C8: ='03_OBSERVATIONS'!C8 | D8: 0 | E8: ='03_OBSERVATIONS'!J8 | F8: 118.4719 | G8: proxy: ASQ-submission timestamp delta, not stopwatch | H8: answer_status=out_of_domain
A9: ='03_OBSERVATIONS'!A9 | B9: ='03_OBSERVATIONS'!B9 | C9: ='03_OBSERVATIONS'!C9 | D9: 0 | E9: ='03_OBSERVATIONS'!J9 | F9: 90.519215 | G9: proxy: ASQ-submission timestamp delta, not stopwatch | H9: answer_status=out_of_domain
A10: ='03_OBSERVATIONS'!A10 | B10: ='03_OBSERVATIONS'!B10 | C10: ='03_OBSERVATIONS'!C10 | D10: 0 | E10: ='03_OBSERVATIONS'!J10 | F10: 71.262827 | G10: proxy: ASQ-submission timestamp delta, not stopwatch | H10: answer_status=fallback_enforced
A11: ='03_OBSERVATIONS'!A11 | B11: ='03_OBSERVATIONS'!B11 | C11: ='03_OBSERVATIONS'!C11 | D11: 0 | E11: ='03_OBSERVATIONS'!J11 | F11: 126.19546 | G11: proxy: ASQ-submission timestamp delta, not stopwatch | H11: answer_status=out_of_domain
A12: ='03_OBSERVATIONS'!A12 | B12: ='03_OBSERVATIONS'!B12 | C12: ='03_OBSERVATIONS'!C12 | E12: ='03_OBSERVATIONS'!J12 | F12: -15.005399 | G12: proxy: ASQ-submission timestamp delta, not stopwatch | H12: no linked turn | I12: negative/invalid completion-time proxy (excluded from clean stats)
A13: ='03_OBSERVATIONS'!A13 | B13: ='03_OBSERVATIONS'!B13 | C13: ='03_OBSERVATIONS'!C13 | D13: 0 | E13: ='03_OBSERVATIONS'!J13 | F13: 29.319702 | G13: proxy: ASQ-submission timestamp delta, not stopwatch | H13: answer_status=out_of_domain
A14: ='03_OBSERVATIONS'!A14 | B14: ='03_OBSERVATIONS'!B14 | C14: ='03_OBSERVATIONS'!C14 | D14: 0 | E14: ='03_OBSERVATIONS'!J14 | F14: 357.88377 | G14: proxy: ASQ-submission timestamp delta, not stopwatch | H14: answer_status=insufficient_context
A15: ='03_OBSERVATIONS'!A15 | B15: ='03_OBSERVATIONS'!B15 | C15: ='03_OBSERVATIONS'!C15 | D15: 1 | E15: ='03_OBSERVATIONS'!J15 | F15: 168.77115 | G15: proxy: ASQ-submission timestamp delta, not stopwatch | H15: answer_status=verified
A16: ='03_OBSERVATIONS'!A16 | B16: ='03_OBSERVATIONS'!B16 | C16: ='03_OBSERVATIONS'!C16 | D16: 0 | E16: ='03_OBSERVATIONS'!J16 | F16: 1755.7589 | G16: proxy: ASQ-submission timestamp delta, not stopwatch | H16: answer_status=out_of_domain
A17: ='03_OBSERVATIONS'!A17 | B17: ='03_OBSERVATIONS'!B17 | C17: ='03_OBSERVATIONS'!C17 | D17: 1 | E17: ='03_OBSERVATIONS'!J17 | F17: 417.86868 | G17: proxy: ASQ-submission timestamp delta, not stopwatch | H17: answer_status=verified
A18: ='03_OBSERVATIONS'!A18 | B18: ='03_OBSERVATIONS'!B18 | C18: ='03_OBSERVATIONS'!C18 | D18: 0 | E18: ='03_OBSERVATIONS'!J18 | F18: 143.08891 | G18: proxy: ASQ-submission timestamp delta, not stopwatch | H18: answer_status=out_of_domain
A19: ='03_OBSERVATIONS'!A19 | B19: ='03_OBSERVATIONS'!B19 | C19: ='03_OBSERVATIONS'!C19 | D19: 0 | E19: ='03_OBSERVATIONS'!J19 | F19: 181.807 | G19: proxy: ASQ-submission timestamp delta, not stopwatch | H19: answer_status=out_of_domain
A20: ='03_OBSERVATIONS'!A20 | B20: ='03_OBSERVATIONS'!B20 | C20: ='03_OBSERVATIONS'!C20 | D20: 0 | E20: ='03_OBSERVATIONS'!J20 | F20: 1912.2165 | G20: proxy: ASQ-submission timestamp delta, not stopwatch | H20: answer_status=insufficient_context
A21: ='03_OBSERVATIONS'!A21 | B21: ='03_OBSERVATIONS'!B21 | C21: ='03_OBSERVATIONS'!C21 | D21: 0 | E21: ='03_OBSERVATIONS'!J21 | F21: 212.97699 | G21: proxy: ASQ-submission timestamp delta, not stopwatch | H21: answer_status=insufficient_context
A22: ='03_OBSERVATIONS'!A22 | B22: ='03_OBSERVATIONS'!B22 | C22: ='03_OBSERVATIONS'!C22 | D22: 0 | E22: ='03_OBSERVATIONS'!J22 | F22: 399.29735 | G22: proxy: ASQ-submission timestamp delta, not stopwatch | H22: answer_status=insufficient_context
A23: ='03_OBSERVATIONS'!A23 | B23: ='03_OBSERVATIONS'!B23 | C23: ='03_OBSERVATIONS'!C23 | D23: 0 | E23: ='03_OBSERVATIONS'!J23 | F23: 316.58634 | G23: proxy: ASQ-submission timestamp delta, not stopwatch | H23: answer_status=insufficient_context
A24: ='03_OBSERVATIONS'!A24 | B24: ='03_OBSERVATIONS'!B24 | C24: ='03_OBSERVATIONS'!C24 | D24: 0 | E24: ='03_OBSERVATIONS'!J24 | F24: 40.466469 | G24: proxy: ASQ-submission timestamp delta, not stopwatch | H24: answer_status=needs_clarification
... A32: ='03_OBSERVATIONS'!A32 | B32: ='03_OBSERVATIONS'!B32 | C32: ='03_OBSERVATIONS'!C32 | D32: 1 | E32: ='03_OBSERVATIONS'!J32 | F32: 330.35588 | G32: proxy: ASQ-submission timestamp delta, not stopwatch | H32: answer_status=verified
A33: ='03_OBSERVATIONS'!A33 | B33: ='03_OBSERVATIONS'!B33 | C33: ='03_OBSERVATIONS'!C33 | D33: 1 | E33: ='03_OBSERVATIONS'!J33 | F33: 15469.873 | G33: proxy: ASQ-submission timestamp delta, not stopwatch | H33: answer_status=verified | I33: >1h outlier, excluded from clean completion-time stats
A34: ='03_OBSERVATIONS'!A34 | B34: ='03_OBSERVATIONS'!B34 | C34: ='03_OBSERVATIONS'!C34 | D34: 1 | E34: ='03_OBSERVATIONS'!J34 | F34: 397.74242 | G34: proxy: ASQ-submission timestamp delta, not stopwatch | H34: answer_status=verified
A35: ='03_OBSERVATIONS'!A35 | B35: ='03_OBSERVATIONS'!B35 | C35: ='03_OBSERVATIONS'!C35 | D35: 0 | E35: ='03_OBSERVATIONS'!J35 | F35: 1092.1194 | G35: proxy: ASQ-submission timestamp delta, not stopwatch | H35: answer_status=fallback_enforced
A36: ='03_OBSERVATIONS'!A36 | B36: ='03_OBSERVATIONS'!B36 | C36: ='03_OBSERVATIONS'!C36 | D36: 0 | E36: ='03_OBSERVATIONS'!J36 | F36: 166.95112 | G36: proxy: ASQ-submission timestamp delta, not stopwatch | H36: answer_status=out_of_domain
A37: ='03_OBSERVATIONS'!A37 | B37: ='03_OBSERVATIONS'!B37 | C37: ='03_OBSERVATIONS'!C37 | D37: 1 | E37: ='03_OBSERVATIONS'!J37 | F37: 244.59629 | G37: proxy: ASQ-submission timestamp delta, not stopwatch | H37: answer_status=verified
A38: ='03_OBSERVATIONS'!A38 | B38: ='03_OBSERVATIONS'!B38 | C38: ='03_OBSERVATIONS'!C38 | D38: 1 | E38: ='03_OBSERVATIONS'!J38 | F38: 292.04439 | G38: proxy: ASQ-submission timestamp delta, not stopwatch | H38: answer_status=verified
A39: ='03_OBSERVATIONS'!A39 | B39: ='03_OBSERVATIONS'!B39 | C39: ='03_OBSERVATIONS'!C39 | D39: 1 | E39: ='03_OBSERVATIONS'!J39 | F39: 10.748128 | G39: proxy: ASQ-submission timestamp delta, not stopwatch | H39: answer_status=verified
A40: ='03_OBSERVATIONS'!A40 | B40: ='03_OBSERVATIONS'!B40 | C40: ='03_OBSERVATIONS'!C40 | D40: 1 | E40: ='03_OBSERVATIONS'!J40 | F40: 108.84884 | G40: proxy: ASQ-submission timestamp delta, not stopwatch | H40: answer_status=verified
A41: ='03_OBSERVATIONS'!A41 | B41: ='03_OBSERVATIONS'!B41 | C41: ='03_OBSERVATIONS'!C41 | D41: 0 | E41: ='03_OBSERVATIONS'!J41 | F41: 6.478247 | G41: proxy: ASQ-submission timestamp delta, not stopwatch | H41: answer_status=out_of_domain
A42: ='03_OBSERVATIONS'!A42 | B42: ='03_OBSERVATIONS'!B42 | C42: ='03_OBSERVATIONS'!C42 | D42: 0 | E42: ='03_OBSERVATIONS'!J42 | F42: 60.753484 | G42: proxy: ASQ-submission timestamp delta, not stopwatch | H42: answer_status=out_of_domain
A43: ='03_OBSERVATIONS'!A43 | B43: ='03_OBSERVATIONS'!B43 | C43: ='03_OBSERVATIONS'!C43 | D43: 0 | E43: ='03_OBSERVATIONS'!J43 | F43: 273672.91 | G43: proxy: ASQ-submission timestamp delta, not stopwatch | H43: answer_status=needs_clarification | I43: >1h outlier, excluded from clean completion-time stats
A44: ='03_OBSERVATIONS'!A44 | B44: ='03_OBSERVATIONS'!B44 | C44: ='03_OBSERVATIONS'!C44 | D44: 1 | E44: ='03_OBSERVATIONS'!J44 | F44: 13.345913 | G44: proxy: ASQ-submission timestamp delta, not stopwatch | H44: answer_status=verified

Sheet 06_SYSTEM_METRICS
A1: observation_id | B1: participant_id | C1: scenario_id | D1: latency_ms | E1: retrieval_latency_ms | F1: llm_latency_ms | G1: retrieved_chunks | H1: graph_nodes_retrieved | I1: graph_relationships | J1: token_input | K1: token_output | L1: model_name | M1: request_status | N1: missing_reason
A2: ='03_OBSERVATIONS'!A2 | B2: ='03_OBSERVATIONS'!B2 | C2: ='03_OBSERVATIONS'!C2 | D2: 8271 | E2: NA | F2: NA | G2: NA | H2: NA | I2: NA | J2: NA | K2: NA | L2: NA | M2: NA | N2: not present in the per-observation safe export; only total end-to-end latency was retained from production chat_evaluation_logs
A3: ='03_OBSERVATIONS'!A3 | B3: ='03_OBSERVATIONS'!B3 | C3: ='03_OBSERVATIONS'!C3 | D3: 10347 | E3: NA | F3: NA | G3: NA | H3: NA | I3: NA | J3: NA | K3: NA | L3: NA | M3: NA | N3: not present in the per-observation safe export; only total end-to-end latency was retained from production chat_evaluation_logs
A4: ='03_OBSERVATIONS'!A4 | B4: ='03_OBSERVATIONS'!B4 | C4: ='03_OBSERVATIONS'!C4 | D4: 20389 | E4: NA | F4: NA | G4: NA | H4: NA | I4: NA | J4: NA | K4: NA | L4: NA | M4: NA | N4: not present in the per-observation safe export; only total end-to-end latency was retained from production chat_evaluation_logs
A5: ='03_OBSERVATIONS'!A5 | B5: ='03_OBSERVATIONS'!B5 | C5: ='03_OBSERVATIONS'!C5 | D5: 6532 | E5: NA | F5: NA | G5: NA | H5: NA | I5: NA | J5: NA | K5: NA | L5: NA | M5: NA | N5: not present in the per-observation safe export; only total end-to-end latency was retained from production chat_evaluation_logs
A6: ='03_OBSERVATIONS'!A6 | B6: ='03_OBSERVATIONS'!B6 | C6: ='03_OBSERVATIONS'!C6 | D6: 12237 | E6: NA | F6: NA | G6: NA | H6: NA | I6: NA | J6: NA | K6: NA | L6: NA | M6: NA | N6: not present in the per-observation safe export; only total end-to-end latency was retained from production chat_evaluation_logs
A7: ='03_OBSERVATIONS'!A7 | B7: ='03_OBSERVATIONS'!B7 | C7: ='03_OBSERVATIONS'!C7 | D7: 6574 | E7: NA | F7: NA | G7: NA | H7: NA | I7: NA | J7: NA | K7: NA | L7: NA | M7: NA | N7: not present in the per-observation safe export; only total end-to-end latency was retained from production chat_evaluation_logs
A8: ='03_OBSERVATIONS'!A8 | B8: ='03_OBSERVATIONS'!B8 | C8: ='03_OBSERVATIONS'!C8 | D8: 5079 | E8: NA | F8: NA | G8: NA | H8: NA | I8: NA | J8: NA | K8: NA | L8: NA | M8: NA | N8: not present in the per-observation safe export; only total end-to-end latency was retained from production chat_evaluation_logs
A9: ='03_OBSERVATIONS'!A9 | B9: ='03_OBSERVATIONS'!B9 | C9: ='03_OBSERVATIONS'!C9 | D9: 5146 | E9: NA | F9: NA | G9: NA | H9: NA | I9: NA | J9: NA | K9: NA | L9: NA | M9: NA | N9: not present in the per-observation safe export; only total end-to-end latency was retained from production chat_evaluation_logs
A10: ='03_OBSERVATIONS'!A10 | B10: ='03_OBSERVATIONS'!B10 | C10: ='03_OBSERVATIONS'!C10 | D10: 36402 | E10: NA | F10: NA | G10: NA | H10: NA | I10: NA | J10: NA | K10: NA | L10: NA | M10: NA | N10: not present in the per-observation safe export; only total end-to-end latency was retained from production chat_evaluation_logs
A11: ='03_OBSERVATIONS'!A11 | B11: ='03_OBSERVATIONS'!B11 | C11: ='03_OBSERVATIONS'!C11 | D11: 5091 | E11: NA | F11: NA | G11: NA | H11: NA | I11: NA | J11: NA | K11: NA | L11: NA | M11: NA | N11: not present in the per-observation safe export; only total end-to-end latency was retained from production chat_evaluation_logs
A12: ='03_OBSERVATIONS'!A12 | B12: ='03_OBSERVATIONS'!B12 | C12: ='03_OBSERVATIONS'!C12 | E12: NA | F12: NA | G12: NA | H12: NA | I12: NA | J12: NA | K12: NA | L12: NA | M12: NA | N12: not present in the per-observation safe export; only total end-to-end latency was retained from production chat_evaluation_logs
A13: ='03_OBSERVATIONS'!A13 | B13: ='03_OBSERVATIONS'!B13 | C13: ='03_OBSERVATIONS'!C13 | D13: 4239 | E13: NA | F13: NA | G13: NA | H13: NA | I13: NA | J13: NA | K13: NA | L13: NA | M13: NA | N13: not present in the per-observation safe export; only total end-to-end latency was retained from production chat_evaluation_logs
A14: ='03_OBSERVATIONS'!A14 | B14: ='03_OBSERVATIONS'!B14 | C14: ='03_OBSERVATIONS'!C14 | D14: 4663 | E14: NA | F14: NA | G14: NA | H14: NA | I14: NA | J14: NA | K14: NA | L14: NA | M14: NA | N14: not present in the per-observation safe export; only total end-to-end latency was retained from production chat_evaluation_logs
A15: ='03_OBSERVATIONS'!A15 | B15: ='03_OBSERVATIONS'!B15 | C15: ='03_OBSERVATIONS'!C15 | D15: 9979 | E15: NA | F15: NA | G15: NA | H15: NA | I15: NA | J15: NA | K15: NA | L15: NA | M15: NA | N15: not present in the per-observation safe export; only total end-to-end latency was retained from production chat_evaluation_logs
A16: ='03_OBSERVATIONS'!A16 | B16: ='03_OBSERVATIONS'!B16 | C16: ='03_OBSERVATIONS'!C16 | D16: 4877 | E16: NA | F16: NA | G16: NA | H16: NA | I16: NA | J16: NA | K16: NA | L16: NA | M16: NA | N16: not present in the per-observation safe export; only total end-to-end latency was retained from production chat_evaluation_logs
A17: ='03_OBSERVATIONS'!A17 | B17: ='03_OBSERVATIONS'!B17 | C17: ='03_OBSERVATIONS'!C17 | D17: 6553 | E17: NA | F17: NA | G17: NA | H17: NA | I17: NA | J17: NA | K17: NA | L17: NA | M17: NA | N17: not present in the per-observation safe export; only total end-to-end latency was retained from production chat_evaluation_logs
A18: ='03_OBSERVATIONS'!A18 | B18: ='03_OBSERVATIONS'!B18 | C18: ='03_OBSERVATIONS'!C18 | D18: 4314 | E18: NA | F18: NA | G18: NA | H18: NA | I18: NA | J18: NA | K18: NA | L18: NA | M18: NA | N18: not present in the per-observation safe export; only total end-to-end latency was retained from production chat_evaluation_logs
A19: ='03_OBSERVATIONS'!A19 | B19: ='03_OBSERVATIONS'!B19 | C19: ='03_OBSERVATIONS'!C19 | D19: 4908 | E19: NA | F19: NA | G19: NA | H19: NA | I19: NA | J19: NA | K19: NA | L19: NA | M19: NA | N19: not present in the per-observation safe export; only total end-to-end latency was retained from production chat_evaluation_logs
A20: ='03_OBSERVATIONS'!A20 | B20: ='03_OBSERVATIONS'!B20 | C20: ='03_OBSERVATIONS'!C20 | D20: 4819 | E20: NA | F20: NA | G20: NA | H20: NA | I20: NA | J20: NA | K20: NA | L20: NA | M20: NA | N20: not present in the per-observation safe export; only total end-to-end latency was retained from production chat_evaluation_logs
A21: ='03_OBSERVATIONS'!A21 | B21: ='03_OBSERVATIONS'!B21 | C21: ='03_OBSERVATIONS'!C21 | D21: 4427 | E21: NA | F21: NA | G21: NA | H21: NA | I21: NA | J21: NA | K21: NA | L21: NA | M21: NA | N21: not present in the per-observation safe export; only total end-to-end latency was retained from production chat_evaluation_logs
A22: ='03_OBSERVATIONS'!A22 | B22: ='03_OBSERVATIONS'!B22 | C22: ='03_OBSERVATIONS'!C22 | D22: 4512 | E22: NA | F22: NA | G22: NA | H22: NA | I22: NA | J22: NA | K22: NA | L22: NA | M22: NA | N22: not present in the per-observation safe export; only total end-to-end latency was retained from production chat_evaluation_logs
A23: ='03_OBSERVATIONS'!A23 | B23: ='03_OBSERVATIONS'!B23 | C23: ='03_OBSERVATIONS'!C23 | D23: 4508 | E23: NA | F23: NA | G23: NA | H23: NA | I23: NA | J23: NA | K23: NA | L23: NA | M23: NA | N23: not present in the per-observation safe export; only total end-to-end latency was retained from production chat_evaluation_logs
A24: ='03_OBSERVATIONS'!A24 | B24: ='03_OBSERVATIONS'!B24 | C24: ='03_OBSERVATIONS'!C24 | D24: 59 | E24: NA | F24: NA | G24: NA | H24: NA | I24: NA | J24: NA | K24: NA | L24: NA | M24: NA | N24: not present in the per-observation safe export; only total end-to-end latency was retained from production chat_evaluation_logs
... A44: ='03_OBSERVATIONS'!A44 | B44: ='03_OBSERVATIONS'!B44 | C44: ='03_OBSERVATIONS'!C44 | D44: 38984 | E44: NA | F44: NA | G44: NA | H44: NA | I44: NA | J44: NA | K44: NA | L44: NA | M44: NA | N44: not present in the per-observation safe export; only total end-to-end latency was retained from production chat_evaluation_logs

Sheet 07_CITATION_EVALUATION
A1: observation_id | B1: participant_id | C1: scenario_id | D1: n_citations | E1: n_valid_citations | F1: has_correct_citation | G1: citation_evaluation_method | H1: evaluator_notes
A2: ='03_OBSERVATIONS'!A2 | B2: ='03_OBSERVATIONS'!B2 | C2: ='03_OBSERVATIONS'!C2 | D2: 4 | E2: 4 | F2: =IF(E2="","",E2>0) | G2: joined via trace_id to production citation_evaluation_logs | H2: Per-observation value tied to these 22 participants via trace_id. NOT the separate 41-question automated gold-QA citation-correct rate (39.0%) -- a different instrument; see 09_STATISTICAL_SUMMARY methodology notes.
A3: ='03_OBSERVATIONS'!A3 | B3: ='03_OBSERVATIONS'!B3 | C3: ='03_OBSERVATIONS'!C3 | D3: 4 | E3: 4 | F3: =IF(E3="","",E3>0) | G3: joined via trace_id to production citation_evaluation_logs
A4: ='03_OBSERVATIONS'!A4 | B4: ='03_OBSERVATIONS'!B4 | C4: ='03_OBSERVATIONS'!C4 | D4: 5 | E4: 5 | F4: =IF(E4="","",E4>0) | G4: joined via trace_id to production citation_evaluation_logs
A5: ='03_OBSERVATIONS'!A5 | B5: ='03_OBSERVATIONS'!B5 | C5: ='03_OBSERVATIONS'!C5 | D5: 4 | E5: 4 | F5: =IF(E5="","",E5>0) | G5: joined via trace_id to production citation_evaluation_logs
A6: ='03_OBSERVATIONS'!A6 | B6: ='03_OBSERVATIONS'!B6 | C6: ='03_OBSERVATIONS'!C6 | D6: 2 | E6: 2 | F6: =IF(E6="","",E6>0) | G6: joined via trace_id to production citation_evaluation_logs
A7: ='03_OBSERVATIONS'!A7 | B7: ='03_OBSERVATIONS'!B7 | C7: ='03_OBSERVATIONS'!C7 | D7: 2 | E7: 2 | F7: =IF(E7="","",E7>0) | G7: joined via trace_id to production citation_evaluation_logs
A8: ='03_OBSERVATIONS'!A8 | B8: ='03_OBSERVATIONS'!B8 | C8: ='03_OBSERVATIONS'!C8 | D8: 0 | E8: 0 | F8: =IF(E8="","",E8>0) | G8: joined via trace_id to production citation_evaluation_logs
A9: ='03_OBSERVATIONS'!A9 | B9: ='03_OBSERVATIONS'!B9 | C9: ='03_OBSERVATIONS'!C9 | D9: 2 | E9: 2 | F9: =IF(E9="","",E9>0) | G9: joined via trace_id to production citation_evaluation_logs
A10: ='03_OBSERVATIONS'!A10 | B10: ='03_OBSERVATIONS'!B10 | C10: ='03_OBSERVATIONS'!C10 | D10: 0 | E10: 0 | F10: =IF(E10="","",E10>0) | G10: joined via trace_id to production citation_evaluation_logs
A11: ='03_OBSERVATIONS'!A11 | B11: ='03_OBSERVATIONS'!B11 | C11: ='03_OBSERVATIONS'!C11 | D11: 2 | E11: 2 | F11: =IF(E11="","",E11>0) | G11: joined via trace_id to production citation_evaluation_logs
A12: ='03_OBSERVATIONS'!A12 | B12: ='03_OBSERVATIONS'!B12 | C12: ='03_OBSERVATIONS'!C12 | D12: 0 | E12: 0 | F12: =IF(E12="","",E12>0) | G12: joined via trace_id to production citation_evaluation_logs
A13: ='03_OBSERVATIONS'!A13 | B13: ='03_OBSERVATIONS'!B13 | C13: ='03_OBSERVATIONS'!C13 | D13: 0 | E13: 0 | F13: =IF(E13="","",E13>0) | G13: joined via trace_id to production citation_evaluation_logs
A14: ='03_OBSERVATIONS'!A14 | B14: ='03_OBSERVATIONS'!B14 | C14: ='03_OBSERVATIONS'!C14 | D14: 0 | E14: 0 | F14: =IF(E14="","",E14>0) | G14: joined via trace_id to production citation_evaluation_logs
... A44: ='03_OBSERVATIONS'!A44 | B44: ='03_OBSERVATIONS'!B44 | C44: ='03_OBSERVATIONS'!C44 | D44: 5 | E44: 5 | F44: =IF(E44="","",E44>0) | G44: joined via trace_id to production citation_evaluation_logs

Sheet 08_MERGED_ANALYSIS
A1: observation_id | B1: participant_id | C1: scenario_id | D1: asq_q1_ease | E1: asq_q2_time | F1: asq_q3_information_support | G1: asq_mean | H1: task_success | I1: task_status | J1: completion_time_sec | K1: latency_ms | L1: has_correct_citation | M1: complete_case_asq | N1: complete_case_performance | O1: paired_scenario_available
A2: ='03_OBSERVATIONS'!A2 | B2: =INDEX('04_ASQ_RESPONSES'!$B:$B,MATCH($A2,'04_ASQ_RESPONSES'!$A:$A,0)) | C2: =INDEX('04_ASQ_RESPONSES'!$C:$C,MATCH($A2,'04_ASQ_RESPONSES'!$A:$A,0)) | D2: =INDEX('04_ASQ_RESPONSES'!$D:$D,MATCH($A2,'04_ASQ_RESPONSES'!$A:$A,0)) | E2: =INDEX('04_ASQ_RESPONSES'!$E:$E,MATCH($A2,'04_ASQ_RESPONSES'!$A:$A,0)) | F2: =INDEX('04_ASQ_RESPONSES'!$F:$F,MATCH($A2,'04_ASQ_RESPONSES'!$A:$A,0)) | G2: =INDEX('04_ASQ_RESPONSES'!$G:$G,MATCH($A2,'04_ASQ_RESPONSES'!$A:$A,0)) | H2: =INDEX('05_TASK_PERFORMANCE'!$D:$D,MATCH($A2,'05_TASK_PERFORMANCE'!$A:$A,0)) | I2: =INDEX('05_TASK_PERFORMANCE'!$E:$E,MATCH($A2,'05_TASK_PERFORMANCE'!$A:$A,0)) | J2: =INDEX('05_TASK_PERFORMANCE'!$F:$F,MATCH($A2,'05_TASK_PERFORMANCE'!$A:$A,0)) | K2: =INDEX('06_SYSTEM_METRICS'!$D:$D,MATCH($A2,'06_SYSTEM_METRICS'!$A:$A,0)) | L2: =INDEX('07_CITATION_EVALUATION'!$F:$F,MATCH($A2,'07_CITATION_EVALUATION'!$A:$A,0)) | M2: =IF(G2<>"",TRUE,FALSE) | N2: =IF(H2<>"",TRUE,FALSE) | O2: =COUNTIF($B$2:$B$44,B2)=2
A3: ='03_OBSERVATIONS'!A3 | B3: =INDEX('04_ASQ_RESPONSES'!$B:$B,MATCH($A3,'04_ASQ_RESPONSES'!$A:$A,0)) | C3: =INDEX('04_ASQ_RESPONSES'!$C:$C,MATCH($A3,'04_ASQ_RESPONSES'!$A:$A,0)) | D3: =INDEX('04_ASQ_RESPONSES'!$D:$D,MATCH($A3,'04_ASQ_RESPONSES'!$A:$A,0)) | E3: =INDEX('04_ASQ_RESPONSES'!$E:$E,MATCH($A3,'04_ASQ_RESPONSES'!$A:$A,0)) | F3: =INDEX('04_ASQ_RESPONSES'!$F:$F,MATCH($A3,'04_ASQ_RESPONSES'!$A:$A,0)) | G3: =INDEX('04_ASQ_RESPONSES'!$G:$G,MATCH($A3,'04_ASQ_RESPONSES'!$A:$A,0)) | H3: =INDEX('05_TASK_PERFORMANCE'!$D:$D,MATCH($A3,'05_TASK_PERFORMANCE'!$A:$A,0)) | I3: =INDEX('05_TASK_PERFORMANCE'!$E:$E,MATCH($A3,'05_TASK_PERFORMANCE'!$A:$A,0)) | J3: =INDEX('05_TASK_PERFORMANCE'!$F:$F,MATCH($A3,'05_TASK_PERFORMANCE'!$A:$A,0)) | K3: =INDEX('06_SYSTEM_METRICS'!$D:$D,MATCH($A3,'06_SYSTEM_METRICS'!$A:$A,0)) | L3: =INDEX('07_CITATION_EVALUATION'!$F:$F,MATCH($A3,'07_CITATION_EVALUATION'!$A:$A,0)) | M3: =IF(G3<>"",TRUE,FALSE) | N3: =IF(H3<>"",TRUE,FALSE) | O3: =COUNTIF($B$2:$B$44,B3)=2
A4: ='03_OBSERVATIONS'!A4 | B4: =INDEX('04_ASQ_RESPONSES'!$B:$B,MATCH($A4,'04_ASQ_RESPONSES'!$A:$A,0)) | C4: =INDEX('04_ASQ_RESPONSES'!$C:$C,MATCH($A4,'04_ASQ_RESPONSES'!$A:$A,0)) | D4: =INDEX('04_ASQ_RESPONSES'!$D:$D,MATCH($A4,'04_ASQ_RESPONSES'!$A:$A,0)) | E4: =INDEX('04_ASQ_RESPONSES'!$E:$E,MATCH($A4,'04_ASQ_RESPONSES'!$A:$A,0)) | F4: =INDEX('04_ASQ_RESPONSES'!$F:$F,MATCH($A4,'04_ASQ_RESPONSES'!$A:$A,0)) | G4: =INDEX('04_ASQ_RESPONSES'!$G:$G,MATCH($A4,'04_ASQ_RESPONSES'!$A:$A,0)) | H4: =INDEX('05_TASK_PERFORMANCE'!$D:$D,MATCH($A4,'05_TASK_PERFORMANCE'!$A:$A,0)) | I4: =INDEX('05_TASK_PERFORMANCE'!$E:$E,MATCH($A4,'05_TASK_PERFORMANCE'!$A:$A,0)) | J4: =INDEX('05_TASK_PERFORMANCE'!$F:$F,MATCH($A4,'05_TASK_PERFORMANCE'!$A:$A,0)) | K4: =INDEX('06_SYSTEM_METRICS'!$D:$D,MATCH($A4,'06_SYSTEM_METRICS'!$A:$A,0)) | L4: =INDEX('07_CITATION_EVALUATION'!$F:$F,MATCH($A4,'07_CITATION_EVALUATION'!$A:$A,0)) | M4: =IF(G4<>"",TRUE,FALSE) | N4: =IF(H4<>"",TRUE,FALSE) | O4: =COUNTIF($B$2:$B$44,B4)=2
A5: ='03_OBSERVATIONS'!A5 | B5: =INDEX('04_ASQ_RESPONSES'!$B:$B,MATCH($A5,'04_ASQ_RESPONSES'!$A:$A,0)) | C5: =INDEX('04_ASQ_RESPONSES'!$C:$C,MATCH($A5,'04_ASQ_RESPONSES'!$A:$A,0)) | D5: =INDEX('04_ASQ_RESPONSES'!$D:$D,MATCH($A5,'04_ASQ_RESPONSES'!$A:$A,0)) | E5: =INDEX('04_ASQ_RESPONSES'!$E:$E,MATCH($A5,'04_ASQ_RESPONSES'!$A:$A,0)) | F5: =INDEX('04_ASQ_RESPONSES'!$F:$F,MATCH($A5,'04_ASQ_RESPONSES'!$A:$A,0)) | G5: =INDEX('04_ASQ_RESPONSES'!$G:$G,MATCH($A5,'04_ASQ_RESPONSES'!$A:$A,0)) | H5: =INDEX('05_TASK_PERFORMANCE'!$D:$D,MATCH($A5,'05_TASK_PERFORMANCE'!$A:$A,0)) | I5: =INDEX('05_TASK_PERFORMANCE'!$E:$E,MATCH($A5,'05_TASK_PERFORMANCE'!$A:$A,0)) | J5: =INDEX('05_TASK_PERFORMANCE'!$F:$F,MATCH($A5,'05_TASK_PERFORMANCE'!$A:$A,0)) | K5: =INDEX('06_SYSTEM_METRICS'!$D:$D,MATCH($A5,'06_SYSTEM_METRICS'!$A:$A,0)) | L5: =INDEX('07_CITATION_EVALUATION'!$F:$F,MATCH($A5,'07_CITATION_EVALUATION'!$A:$A,0)) | M5: =IF(G5<>"",TRUE,FALSE) | N5: =IF(H5<>"",TRUE,FALSE) | O5: =COUNTIF($B$2:$B$44,B5)=2
A6: ='03_OBSERVATIONS'!A6 | B6: =INDEX('04_ASQ_RESPONSES'!$B:$B,MATCH($A6,'04_ASQ_RESPONSES'!$A:$A,0)) | C6: =INDEX('04_ASQ_RESPONSES'!$C:$C,MATCH($A6,'04_ASQ_RESPONSES'!$A:$A,0)) | D6: =INDEX('04_ASQ_RESPONSES'!$D:$D,MATCH($A6,'04_ASQ_RESPONSES'!$A:$A,0)) | E6: =INDEX('04_ASQ_RESPONSES'!$E:$E,MATCH($A6,'04_ASQ_RESPONSES'!$A:$A,0)) | F6: =INDEX('04_ASQ_RESPONSES'!$F:$F,MATCH($A6,'04_ASQ_RESPONSES'!$A:$A,0)) | G6: =INDEX('04_ASQ_RESPONSES'!$G:$G,MATCH($A6,'04_ASQ_RESPONSES'!$A:$A,0)) | H6: =INDEX('05_TASK_PERFORMANCE'!$D:$D,MATCH($A6,'05_TASK_PERFORMANCE'!$A:$A,0)) | I6: =INDEX('05_TASK_PERFORMANCE'!$E:$E,MATCH($A6,'05_TASK_PERFORMANCE'!$A:$A,0)) | J6: =INDEX('05_TASK_PERFORMANCE'!$F:$F,MATCH($A6,'05_TASK_PERFORMANCE'!$A:$A,0)) | K6: =INDEX('06_SYSTEM_METRICS'!$D:$D,MATCH($A6,'06_SYSTEM_METRICS'!$A:$A,0)) | L6: =INDEX('07_CITATION_EVALUATION'!$F:$F,MATCH($A6,'07_CITATION_EVALUATION'!$A:$A,0)) | M6: =IF(G6<>"",TRUE,FALSE) | N6: =IF(H6<>"",TRUE,FALSE) | O6: =COUNTIF($B$2:$B$44,B6)=2
A7: ='03_OBSERVATIONS'!A7 | B7: =INDEX('04_ASQ_RESPONSES'!$B:$B,MATCH($A7,'04_ASQ_RESPONSES'!$A:$A,0)) | C7: =INDEX('04_ASQ_RESPONSES'!$C:$C,MATCH($A7,'04_ASQ_RESPONSES'!$A:$A,0)) | D7: =INDEX('04_ASQ_RESPONSES'!$D:$D,MATCH($A7,'04_ASQ_RESPONSES'!$A:$A,0)) | E7: =INDEX('04_ASQ_RESPONSES'!$E:$E,MATCH($A7,'04_ASQ_RESPONSES'!$A:$A,0)) | F7: =INDEX('04_ASQ_RESPONSES'!$F:$F,MATCH($A7,'04_ASQ_RESPONSES'!$A:$A,0)) | G7: =INDEX('04_ASQ_RESPONSES'!$G:$G,MATCH($A7,'04_ASQ_RESPONSES'!$A:$A,0)) | H7: =INDEX('05_TASK_PERFORMANCE'!$D:$D,MATCH($A7,'05_TASK_PERFORMANCE'!$A:$A,0)) | I7: =INDEX('05_TASK_PERFORMANCE'!$E:$E,MATCH($A7,'05_TASK_PERFORMANCE'!$A:$A,0)) | J7: =INDEX('05_TASK_PERFORMANCE'!$F:$F,MATCH($A7,'05_TASK_PERFORMANCE'!$A:$A,0)) | K7: =INDEX('06_SYSTEM_METRICS'!$D:$D,MATCH($A7,'06_SYSTEM_METRICS'!$A:$A,0)) | L7: =INDEX('07_CITATION_EVALUATION'!$F:$F,MATCH($A7,'07_CITATION_EVALUATION'!$A:$A,0)) | M7: =IF(G7<>"",TRUE,FALSE) | N7: =IF(H7<>"",TRUE,FALSE) | O7: =COUNTIF($B$2:$B$44,B7)=2
A8: ='03_OBSERVATIONS'!A8 | B8: =INDEX('04_ASQ_RESPONSES'!$B:$B,MATCH($A8,'04_ASQ_RESPONSES'!$A:$A,0)) | C8: =INDEX('04_ASQ_RESPONSES'!$C:$C,MATCH($A8,'04_ASQ_RESPONSES'!$A:$A,0)) | D8: =INDEX('04_ASQ_RESPONSES'!$D:$D,MATCH($A8,'04_ASQ_RESPONSES'!$A:$A,0)) | E8: =INDEX('04_ASQ_RESPONSES'!$E:$E,MATCH($A8,'04_ASQ_RESPONSES'!$A:$A,0)) | F8: =INDEX('04_ASQ_RESPONSES'!$F:$F,MATCH($A8,'04_ASQ_RESPONSES'!$A:$A,0)) | G8: =INDEX('04_ASQ_RESPONSES'!$G:$G,MATCH($A8,'04_ASQ_RESPONSES'!$A:$A,0)) | H8: =INDEX('05_TASK_PERFORMANCE'!$D:$D,MATCH($A8,'05_TASK_PERFORMANCE'!$A:$A,0)) | I8: =INDEX('05_TASK_PERFORMANCE'!$E:$E,MATCH($A8,'05_TASK_PERFORMANCE'!$A:$A,0)) | J8: =INDEX('05_TASK_PERFORMANCE'!$F:$F,MATCH($A8,'05_TASK_PERFORMANCE'!$A:$A,0)) | K8: =INDEX('06_SYSTEM_METRICS'!$D:$D,MATCH($A8,'06_SYSTEM_METRICS'!$A:$A,0)) | L8: =INDEX('07_CITATION_EVALUATION'!$F:$F,MATCH($A8,'07_CITATION_EVALUATION'!$A:$A,0)) | M8: =IF(G8<>"",TRUE,FALSE) | N8: =IF(H8<>"",TRUE,FALSE) | O8: =COUNTIF($B$2:$B$44,B8)=2
A9: ='03_OBSERVATIONS'!A9 | B9: =INDEX('04_ASQ_RESPONSES'!$B:$B,MATCH($A9,'04_ASQ_RESPONSES'!$A:$A,0)) | C9: =INDEX('04_ASQ_RESPONSES'!$C:$C,MATCH($A9,'04_ASQ_RESPONSES'!$A:$A,0)) | D9: =INDEX('04_ASQ_RESPONSES'!$D:$D,MATCH($A9,'04_ASQ_RESPONSES'!$A:$A,0)) | E9: =INDEX('04_ASQ_RESPONSES'!$E:$E,MATCH($A9,'04_ASQ_RESPONSES'!$A:$A,0)) | F9: =INDEX('04_ASQ_RESPONSES'!$F:$F,MATCH($A9,'04_ASQ_RESPONSES'!$A:$A,0)) | G9: =INDEX('04_ASQ_RESPONSES'!$G:$G,MATCH($A9,'04_ASQ_RESPONSES'!$A:$A,0)) | H9: =INDEX('05_TASK_PERFORMANCE'!$D:$D,MATCH($A9,'05_TASK_PERFORMANCE'!$A:$A,0)) | I9: =INDEX('05_TASK_PERFORMANCE'!$E:$E,MATCH($A9,'05_TASK_PERFORMANCE'!$A:$A,0)) | J9: =INDEX('05_TASK_PERFORMANCE'!$F:$F,MATCH($A9,'05_TASK_PERFORMANCE'!$A:$A,0)) | K9: =INDEX('06_SYSTEM_METRICS'!$D:$D,MATCH($A9,'06_SYSTEM_METRICS'!$A:$A,0)) | L9: =INDEX('07_CITATION_EVALUATION'!$F:$F,MATCH($A9,'07_CITATION_EVALUATION'!$A:$A,0)) | M9: =IF(G9<>"",TRUE,FALSE) | N9: =IF(H9<>"",TRUE,FALSE) | O9: =COUNTIF($B$2:$B$44,B9)=2
A10: ='03_OBSERVATIONS'!A10 | B10: =INDEX('04_ASQ_RESPONSES'!$B:$B,MATCH($A10,'04_ASQ_RESPONSES'!$A:$A,0)) | C10: =INDEX('04_ASQ_RESPONSES'!$C:$C,MATCH($A10,'04_ASQ_RESPONSES'!$A:$A,0)) | D10: =INDEX('04_ASQ_RESPONSES'!$D:$D,MATCH($A10,'04_ASQ_RESPONSES'!$A:$A,0)) | E10: =INDEX('04_ASQ_RESPONSES'!$E:$E,MATCH($A10,'04_ASQ_RESPONSES'!$A:$A,0)) | F10: =INDEX('04_ASQ_RESPONSES'!$F:$F,MATCH($A10,'04_ASQ_RESPONSES'!$A:$A,0)) | G10: =INDEX('04_ASQ_RESPONSES'!$G:$G,MATCH($A10,'04_ASQ_RESPONSES'!$A:$A,0)) | H10: =INDEX('05_TASK_PERFORMANCE'!$D:$D,MATCH($A10,'05_TASK_PERFORMANCE'!$A:$A,0)) | I10: =INDEX('05_TASK_PERFORMANCE'!$E:$E,MATCH($A10,'05_TASK_PERFORMANCE'!$A:$A,0)) | J10: =INDEX('05_TASK_PERFORMANCE'!$F:$F,MATCH($A10,'05_TASK_PERFORMANCE'!$A:$A,0)) | K10: =INDEX('06_SYSTEM_METRICS'!$D:$D,MATCH($A10,'06_SYSTEM_METRICS'!$A:$A,0)) | L10: =INDEX('07_CITATION_EVALUATION'!$F:$F,MATCH($A10,'07_CITATION_EVALUATION'!$A:$A,0)) | M10: =IF(G10<>"",TRUE,FALSE) | N10: =IF(H10<>"",TRUE,FALSE) | O10: =COUNTIF($B$2:$B$44,B10)=2
A11: ='03_OBSERVATIONS'!A11 | B11: =INDEX('04_ASQ_RESPONSES'!$B:$B,MATCH($A11,'04_ASQ_RESPONSES'!$A:$A,0)) | C11: =INDEX('04_ASQ_RESPONSES'!$C:$C,MATCH($A11,'04_ASQ_RESPONSES'!$A:$A,0)) | D11: =INDEX('04_ASQ_RESPONSES'!$D:$D,MATCH($A11,'04_ASQ_RESPONSES'!$A:$A,0)) | E11: =INDEX('04_ASQ_RESPONSES'!$E:$E,MATCH($A11,'04_ASQ_RESPONSES'!$A:$A,0)) | F11: =INDEX('04_ASQ_RESPONSES'!$F:$F,MATCH($A11,'04_ASQ_RESPONSES'!$A:$A,0)) | G11: =INDEX('04_ASQ_RESPONSES'!$G:$G,MATCH($A11,'04_ASQ_RESPONSES'!$A:$A,0)) | H11: =INDEX('05_TASK_PERFORMANCE'!$D:$D,MATCH($A11,'05_TASK_PERFORMANCE'!$A:$A,0)) | I11: =INDEX('05_TASK_PERFORMANCE'!$E:$E,MATCH($A11,'05_TASK_PERFORMANCE'!$A:$A,0)) | J11: =INDEX('05_TASK_PERFORMANCE'!$F:$F,MATCH($A11,'05_TASK_PERFORMANCE'!$A:$A,0)) | K11: =INDEX('06_SYSTEM_METRICS'!$D:$D,MATCH($A11,'06_SYSTEM_METRICS'!$A:$A,0)) | L11: =INDEX('07_CITATION_EVALUATION'!$F:$F,MATCH($A11,'07_CITATION_EVALUATION'!$A:$A,0)) | M11: =IF(G11<>"",TRUE,FALSE) | N11: =IF(H11<>"",TRUE,FALSE) | O11: =COUNTIF($B$2:$B$44,B11)=2
A12: ='03_OBSERVATIONS'!A12 | B12: =INDEX('04_ASQ_RESPONSES'!$B:$B,MATCH($A12,'04_ASQ_RESPONSES'!$A:$A,0)) | C12: =INDEX('04_ASQ_RESPONSES'!$C:$C,MATCH($A12,'04_ASQ_RESPONSES'!$A:$A,0)) | D12: =INDEX('04_ASQ_RESPONSES'!$D:$D,MATCH($A12,'04_ASQ_RESPONSES'!$A:$A,0)) | E12: =INDEX('04_ASQ_RESPONSES'!$E:$E,MATCH($A12,'04_ASQ_RESPONSES'!$A:$A,0)) | F12: =INDEX('04_ASQ_RESPONSES'!$F:$F,MATCH($A12,'04_ASQ_RESPONSES'!$A:$A,0)) | G12: =INDEX('04_ASQ_RESPONSES'!$G:$G,MATCH($A12,'04_ASQ_RESPONSES'!$A:$A,0)) | H12: =INDEX('05_TASK_PERFORMANCE'!$D:$D,MATCH($A12,'05_TASK_PERFORMANCE'!$A:$A,0)) | I12: =INDEX('05_TASK_PERFORMANCE'!$E:$E,MATCH($A12,'05_TASK_PERFORMANCE'!$A:$A,0)) | J12: =INDEX('05_TASK_PERFORMANCE'!$F:$F,MATCH($A12,'05_TASK_PERFORMANCE'!$A:$A,0)) | K12: =INDEX('06_SYSTEM_METRICS'!$D:$D,MATCH($A12,'06_SYSTEM_METRICS'!$A:$A,0)) | L12: =INDEX('07_CITATION_EVALUATION'!$F:$F,MATCH($A12,'07_CITATION_EVALUATION'!$A:$A,0)) | M12: =IF(G12<>"",TRUE,FALSE) | N12: =IF(H12<>"",TRUE,FALSE) | O12: =COUNTIF($B$2:$B$44,B12)=2
A13: ='03_OBSERVATIONS'!A13 | B13: =INDEX('04_ASQ_RESPONSES'!$B:$B,MATCH($A13,'04_ASQ_RESPONSES'!$A:$A,0)) | C13: =INDEX('04_ASQ_RESPONSES'!$C:$C,MATCH($A13,'04_ASQ_RESPONSES'!$A:$A,0)) | D13: =INDEX('04_ASQ_RESPONSES'!$D:$D,MATCH($A13,'04_ASQ_RESPONSES'!$A:$A,0)) | E13: =INDEX('04_ASQ_RESPONSES'!$E:$E,MATCH($A13,'04_ASQ_RESPONSES'!$A:$A,0)) | F13: =INDEX('04_ASQ_RESPONSES'!$F:$F,MATCH($A13,'04_ASQ_RESPONSES'!$A:$A,0)) | G13: =INDEX('04_ASQ_RESPONSES'!$G:$G,MATCH($A13,'04_ASQ_RESPONSES'!$A:$A,0)) | H13: =INDEX('05_TASK_PERFORMANCE'!$D:$D,MATCH($A13,'05_TASK_PERFORMANCE'!$A:$A,0)) | I13: =INDEX('05_TASK_PERFORMANCE'!$E:$E,MATCH($A13,'05_TASK_PERFORMANCE'!$A:$A,0)) | J13: =INDEX('05_TASK_PERFORMANCE'!$F:$F,MATCH($A13,'05_TASK_PERFORMANCE'!$A:$A,0)) | K13: =INDEX('06_SYSTEM_METRICS'!$D:$D,MATCH($A13,'06_SYSTEM_METRICS'!$A:$A,0)) | L13: =INDEX('07_CITATION_EVALUATION'!$F:$F,MATCH($A13,'07_CITATION_EVALUATION'!$A:$A,0)) | M13: =IF(G13<>"",TRUE,FALSE) | N13: =IF(H13<>"",TRUE,FALSE) | O13: =COUNTIF($B$2:$B$44,B13)=2
... A44: ='03_OBSERVATIONS'!A44 | B44: =INDEX('04_ASQ_RESPONSES'!$B:$B,MATCH($A44,'04_ASQ_RESPONSES'!$A:$A,0)) | C44: =INDEX('04_ASQ_RESPONSES'!$C:$C,MATCH($A44,'04_ASQ_RESPONSES'!$A:$A,0)) | D44: =INDEX('04_ASQ_RESPONSES'!$D:$D,MATCH($A44,'04_ASQ_RESPONSES'!$A:$A,0)) | E44: =INDEX('04_ASQ_RESPONSES'!$E:$E,MATCH($A44,'04_ASQ_RESPONSES'!$A:$A,0)) | F44: =INDEX('04_ASQ_RESPONSES'!$F:$F,MATCH($A44,'04_ASQ_RESPONSES'!$A:$A,0)) | G44: =INDEX('04_ASQ_RESPONSES'!$G:$G,MATCH($A44,'04_ASQ_RESPONSES'!$A:$A,0)) | H44: =INDEX('05_TASK_PERFORMANCE'!$D:$D,MATCH($A44,'05_TASK_PERFORMANCE'!$A:$A,0)) | I44: =INDEX('05_TASK_PERFORMANCE'!$E:$E,MATCH($A44,'05_TASK_PERFORMANCE'!$A:$A,0)) | J44: =INDEX('05_TASK_PERFORMANCE'!$F:$F,MATCH($A44,'05_TASK_PERFORMANCE'!$A:$A,0)) | K44: =INDEX('06_SYSTEM_METRICS'!$D:$D,MATCH($A44,'06_SYSTEM_METRICS'!$A:$A,0)) | L44: =INDEX('07_CITATION_EVALUATION'!$F:$F,MATCH($A44,'07_CITATION_EVALUATION'!$A:$A,0)) | M44: =IF(G44<>"",TRUE,FALSE) | N44: =IF(H44<>"",TRUE,FALSE) | O44: =COUNTIF($B$2:$B$44,B44)=2

Sheet 09_STATISTICAL_SUMMARY
A1: A. Descriptive Statistics -- ASQ mean score | N1: helper: asq_mean_s1 | O1: helper: asq_mean_s2 | P1: helper: q1_s1 | Q1: helper: q2_s1 | R1: helper: q3_s1 | S1: helper: q1_s2 | T1: helper: q2_s2 | U1: helper: q3_s2 | V1: helper: total_s1 | W1: helper: total_s2 | X1: helper: completion_s1_clean | Y1: helper: completion_s2_clean | Z1: helper: latency_s1 | AA1: helper: latency_s2 | AB1: helper: asq_mean_success1 | AC1: helper: asq_mean_success0 | AD1: helper: asq3_for_citation | AE1: helper: citation_as_number
N2: =IF('08_MERGED_ANALYSIS'!C2="S1",'08_MERGED_ANALYSIS'!G2,"") | O2: =IF('08_MERGED_ANALYSIS'!C2="S2",'08_MERGED_ANALYSIS'!G2,"") | P2: =IF('08_MERGED_ANALYSIS'!C2="S1",'08_MERGED_ANALYSIS'!D2,"") | Q2: =IF('08_MERGED_ANALYSIS'!C2="S1",'08_MERGED_ANALYSIS'!E2,"") | R2: =IF('08_MERGED_ANALYSIS'!C2="S1",'08_MERGED_ANALYSIS'!F2,"") | S2: =IF('08_MERGED_ANALYSIS'!C2="S2",'08_MERGED_ANALYSIS'!D2,"") | T2: =IF('08_MERGED_ANALYSIS'!C2="S2",'08_MERGED_ANALYSIS'!E2,"") | U2: =IF('08_MERGED_ANALYSIS'!C2="S2",'08_MERGED_ANALYSIS'!F2,"") | V2: =IF(P2="","",P2+Q2+R2) | W2: =IF(S2="","",S2+T2+U2) | X2: =IF(AND('08_MERGED_ANALYSIS'!C2="S1",'08_MERGED_ANALYSIS'!J2<>"",'08_MERGED_ANALYSIS'!J2>=0,'08_MERGED_ANALYSIS'!J2<=3600),'08_MERGED_ANALYSIS'!J2,"") | Y2: =IF(AND('08_MERGED_ANALYSIS'!C2="S2",'08_MERGED_ANALYSIS'!J2<>"",'08_MERGED_ANALYSIS'!J2>=0,'08_MERGED_ANALYSIS'!J2<=3600),'08_MERGED_ANALYSIS'!J2,"") | Z2: =IF('08_MERGED_ANALYSIS'!C2="S1",'08_MERGED_ANALYSIS'!K2,"") | AA2: =IF('08_MERGED_ANALYSIS'!C2="S2",'08_MERGED_ANALYSIS'!K2,"") | AB2: =IF('08_MERGED_ANALYSIS'!H2=1,'08_MERGED_ANALYSIS'!G2,"") | AC2: =IF('08_MERGED_ANALYSIS'!H2=0,'08_MERGED_ANALYSIS'!G2,"") | AD2: =IF('08_MERGED_ANALYSIS'!L2<>"",'08_MERGED_ANALYSIS'!F2,"") | AE2: =IF('08_MERGED_ANALYSIS'!L2<>"",IF('08_MERGED_ANALYSIS'!L2,1,0),"")
A3: Statistic | B3: Overall | C3: S1 | D3: S2 | N3: =IF('08_MERGED_ANALYSIS'!C3="S1",'08_MERGED_ANALYSIS'!G3,"") | O3: =IF('08_MERGED_ANALYSIS'!C3="S2",'08_MERGED_ANALYSIS'!G3,"") | P3: =IF('08_MERGED_ANALYSIS'!C3="S1",'08_MERGED_ANALYSIS'!D3,"") | Q3: =IF('08_MERGED_ANALYSIS'!C3="S1",'08_MERGED_ANALYSIS'!E3,"") | R3: =IF('08_MERGED_ANALYSIS'!C3="S1",'08_MERGED_ANALYSIS'!F3,"") | S3: =IF('08_MERGED_ANALYSIS'!C3="S2",'08_MERGED_ANALYSIS'!D3,"") | T3: =IF('08_MERGED_ANALYSIS'!C3="S2",'08_MERGED_ANALYSIS'!E3,"") | U3: =IF('08_MERGED_ANALYSIS'!C3="S2",'08_MERGED_ANALYSIS'!F3,"") | V3: =IF(P3="","",P3+Q3+R3) | W3: =IF(S3="","",S3+T3+U3) | X3: =IF(AND('08_MERGED_ANALYSIS'!C3="S1",'08_MERGED_ANALYSIS'!J3<>"",'08_MERGED_ANALYSIS'!J3>=0,'08_MERGED_ANALYSIS'!J3<=3600),'08_MERGED_ANALYSIS'!J3,"") | Y3: =IF(AND('08_MERGED_ANALYSIS'!C3="S2",'08_MERGED_ANALYSIS'!J3<>"",'08_MERGED_ANALYSIS'!J3>=0,'08_MERGED_ANALYSIS'!J3<=3600),'08_MERGED_ANALYSIS'!J3,"") | Z3: =IF('08_MERGED_ANALYSIS'!C3="S1",'08_MERGED_ANALYSIS'!K3,"") | AA3: =IF('08_MERGED_ANALYSIS'!C3="S2",'08_MERGED_ANALYSIS'!K3,"") | AB3: =IF('08_MERGED_ANALYSIS'!H3=1,'08_MERGED_ANALYSIS'!G3,"") | AC3: =IF('08_MERGED_ANALYSIS'!H3=0,'08_MERGED_ANALYSIS'!G3,"") | AD3: =IF('08_MERGED_ANALYSIS'!L3<>"",'08_MERGED_ANALYSIS'!F3,"") | AE3: =IF('08_MERGED_ANALYSIS'!L3<>"",IF('08_MERGED_ANALYSIS'!L3,1,0),"")
